Insult Filter service running at port 50152 with name InsultFilterService_0
Insult Filter service running at port 50152 with name InsultFilterService_0
Insult Filter service running at port 50152 with name InsultFilterService_0
Insult Filter service running at port 50152 with name InsultFilterService_0
Insult Filter service running at port 50152 with name InsultFilterService_0
Insult Filter service running at port 50152 with name InsultFilterService_0
Insult Filter service running at port 50152 with name InsultFilterService_0
Insult Filter service running at port 50152 with name InsultFilterService_0
Insult Filter service running at port 50152 with name InsultFilterService_0
Insult Filter service running at port 50152 with name InsultFilterService_0
Insult Filter service running at port 50152 with name InsultFilterService_0
Insult Filter service running at port 50152 with name InsultFilterService_0
Insult Filter service running at port 50152 with name InsultFilterService_0
Insult Filter service running at port 50152 with name InsultFilterService_0
Insult Filter service running at port 50152 with name InsultFilterService_0
Insult Filter service running at port 50152 with name InsultFilterService_0
Insult Filter service running at port 50152 with name InsultFilterService_0
Insult Filter service running at port 50152 with name InsultFilterService_0
Insult Filter service running at port 50152 with name InsultFilterService_0
Insult Filter service running at port 50152 with name InsultFilterService_0
Insult Filter service running at port 50152 with name InsultFilterService_0
Insult Filter service running at port 50152 with name InsultFilterService_0
Insult Filter service running at port 50152 with name InsultFilterService_0
Insult Filter service running at port 50152 with name InsultFilterService_0
Insult Filter service running at port 50152 with name InsultFilterService_0
Insult Filter service running at port 50152 with name InsultFilterService_0
Traceback (most recent call last):
  File "/usr/local/lib/python3.11/dist-packages/Pyro4/core.py", line 511, in connect_and_handshake
    sock = socketutil.createSocket(connect=connect_location,
           ^^^^^^^^^^^^^^^^^^^^^^^^^^^^^^^^^^^^^^^^^^^^^^^^^
  File "/usr/local/lib/python3.11/dist-packages/Pyro4/socketutil.py", line 307, in createSocket
    sock.connect(connect)
ConnectionRefusedError: [Errno 111] Connection refused

The above exception was the direct cause of the following exception:

Traceback (most recent call last):
  File "/usr/local/lib/python3.11/dist-packages/Pyro4/core.py", line 2009, in _locateNS
    proxy._pyroBind()
  File "/usr/local/lib/python3.11/dist-packages/Pyro4/core.py", line 408, in _pyroBind
    return self.__pyroCreateConnection(True)
           ^^^^^^^^^^^^^^^^^^^^^^^^^^^^^^^^^
  File "/usr/local/lib/python3.11/dist-packages/Pyro4/core.py", line 596, in __pyroCreateConnection
    connect_and_handshake(conn)
  File "/usr/local/lib/python3.11/dist-packages/Pyro4/core.py", line 549, in connect_and_handshake
    raise ce
Pyro4.errors.CommunicationError: cannot connect to ('localhost', 9090): [Errno 111] Connection refused

The above exception was the direct cause of the following exception:

Traceback (most recent call last):
  File "/home/milax/SD/sd_p1/dynamic-scaling/InsultFilterService/server.py", line 104, in <module>
    ns = Pyro4.locateNS()
         ^^^^^^^^^^^^^^^^
  File "/usr/local/lib/python3.11/dist-packages/Pyro4/core.py", line 2016, in _locateNS
    raise e
Pyro4.errors.NamingError: Failed to locate the nameserver
Insult Filter service running at port 50152 with name InsultFilterService_0
Insult Filter service running at port 50152 with name InsultFilterService_0
Insult Filter service running at port 50152 with name InsultFilterService_0
Insult Filter service running at port 50152 with name InsultFilterService_0
Traceback (most recent call last):
  File "/home/milax/SD/sd_p1/dynamic-scaling/InsultFilterService/server.py", line 103, in <module>
    daemon = Pyro4.Daemon(port=port)
             ^^^^^^^^^^^^^^^^^^^^^^^
  File "/home/milax/SD/sd_p1/dynamic-scaling/venv/lib/python3.11/site-packages/Pyro4/core.py", line 1141, in __init__
    self.transportServer.init(self, host, port, unixsocket)
  File "/home/milax/SD/sd_p1/dynamic-scaling/venv/lib/python3.11/site-packages/Pyro4/socketserver/threadpoolserver.py", line 129, in init
    self.sock = socketutil.createSocket(bind=bind_location,
                ^^^^^^^^^^^^^^^^^^^^^^^^^^^^^^^^^^^^^^^^^^^
  File "/home/milax/SD/sd_p1/dynamic-scaling/venv/lib/python3.11/site-packages/Pyro4/socketutil.py", line 300, in createSocket
    sock.bind(bind)
OSError: [Errno 98] Address already in use
Insult Filter service running at port 50152 with name InsultFilterService_0
Traceback (most recent call last):
  File "/home/milax/SD/sd_p1/dynamic-scaling/InsultFilterService/server.py", line 103, in <module>
    daemon = Pyro4.Daemon(port=port)
             ^^^^^^^^^^^^^^^^^^^^^^^
  File "/home/milax/SD/sd_p1/dynamic-scaling/venv/lib/python3.11/site-packages/Pyro4/core.py", line 1141, in __init__
    self.transportServer.init(self, host, port, unixsocket)
  File "/home/milax/SD/sd_p1/dynamic-scaling/venv/lib/python3.11/site-packages/Pyro4/socketserver/threadpoolserver.py", line 129, in init
    self.sock = socketutil.createSocket(bind=bind_location,
                ^^^^^^^^^^^^^^^^^^^^^^^^^^^^^^^^^^^^^^^^^^^
  File "/home/milax/SD/sd_p1/dynamic-scaling/venv/lib/python3.11/site-packages/Pyro4/socketutil.py", line 300, in createSocket
    sock.bind(bind)
OSError: [Errno 98] Address already in use
Insult Filter service running at port 50152 with name InsultFilterService_0
Traceback (most recent call last):
  File "/home/milax/SD/sd_p1/dynamic-scaling/InsultFilterService/server.py", line 103, in <module>
    daemon = Pyro4.Daemon(port=port)
             ^^^^^^^^^^^^^^^^^^^^^^^
  File "/home/milax/SD/sd_p1/dynamic-scaling/venv/lib/python3.11/site-packages/Pyro4/core.py", line 1141, in __init__
    self.transportServer.init(self, host, port, unixsocket)
  File "/home/milax/SD/sd_p1/dynamic-scaling/venv/lib/python3.11/site-packages/Pyro4/socketserver/threadpoolserver.py", line 129, in init
    self.sock = socketutil.createSocket(bind=bind_location,
                ^^^^^^^^^^^^^^^^^^^^^^^^^^^^^^^^^^^^^^^^^^^
  File "/home/milax/SD/sd_p1/dynamic-scaling/venv/lib/python3.11/site-packages/Pyro4/socketutil.py", line 300, in createSocket
    sock.bind(bind)
OSError: [Errno 98] Address already in use
Insult Filter service running at port 50152 with name InsultFilterService_0
Traceback (most recent call last):
  File "/home/milax/SD/sd_p1/dynamic-scaling/InsultFilterService/server.py", line 103, in <module>
    daemon = Pyro4.Daemon(port=port)
             ^^^^^^^^^^^^^^^^^^^^^^^
  File "/home/milax/SD/sd_p1/dynamic-scaling/venv/lib/python3.11/site-packages/Pyro4/core.py", line 1141, in __init__
    self.transportServer.init(self, host, port, unixsocket)
  File "/home/milax/SD/sd_p1/dynamic-scaling/venv/lib/python3.11/site-packages/Pyro4/socketserver/threadpoolserver.py", line 129, in init
    self.sock = socketutil.createSocket(bind=bind_location,
                ^^^^^^^^^^^^^^^^^^^^^^^^^^^^^^^^^^^^^^^^^^^
  File "/home/milax/SD/sd_p1/dynamic-scaling/venv/lib/python3.11/site-packages/Pyro4/socketutil.py", line 300, in createSocket
    sock.bind(bind)
OSError: [Errno 98] Address already in use
Insult Filter service running at port 50152 with name InsultFilterService_0
Traceback (most recent call last):
  File "/home/milax/SD/sd_p1/dynamic-scaling/InsultFilterService/server.py", line 103, in <module>
    daemon = Pyro4.Daemon(port=port)
             ^^^^^^^^^^^^^^^^^^^^^^^
  File "/home/milax/SD/sd_p1/dynamic-scaling/venv/lib/python3.11/site-packages/Pyro4/core.py", line 1141, in __init__
    self.transportServer.init(self, host, port, unixsocket)
  File "/home/milax/SD/sd_p1/dynamic-scaling/venv/lib/python3.11/site-packages/Pyro4/socketserver/threadpoolserver.py", line 129, in init
    self.sock = socketutil.createSocket(bind=bind_location,
                ^^^^^^^^^^^^^^^^^^^^^^^^^^^^^^^^^^^^^^^^^^^
  File "/home/milax/SD/sd_p1/dynamic-scaling/venv/lib/python3.11/site-packages/Pyro4/socketutil.py", line 300, in createSocket
    sock.bind(bind)
OSError: [Errno 98] Address already in use
Insult Filter service running at port 50152 with name InsultFilterService_0
Traceback (most recent call last):
  File "/home/milax/SD/sd_p1/dynamic-scaling/InsultFilterService/server.py", line 103, in <module>
    daemon = Pyro4.Daemon(port=port)
             ^^^^^^^^^^^^^^^^^^^^^^^
  File "/home/milax/SD/sd_p1/dynamic-scaling/venv/lib/python3.11/site-packages/Pyro4/core.py", line 1141, in __init__
    self.transportServer.init(self, host, port, unixsocket)
  File "/home/milax/SD/sd_p1/dynamic-scaling/venv/lib/python3.11/site-packages/Pyro4/socketserver/threadpoolserver.py", line 129, in init
    self.sock = socketutil.createSocket(bind=bind_location,
                ^^^^^^^^^^^^^^^^^^^^^^^^^^^^^^^^^^^^^^^^^^^
  File "/home/milax/SD/sd_p1/dynamic-scaling/venv/lib/python3.11/site-packages/Pyro4/socketutil.py", line 300, in createSocket
    sock.bind(bind)
OSError: [Errno 98] Address already in use
Insult Filter service running at port 50152 with name InsultFilterService_0
Traceback (most recent call last):
  File "/home/milax/SD/sd_p1/dynamic-scaling/InsultFilterService/server.py", line 103, in <module>
    daemon = Pyro4.Daemon(port=port)
             ^^^^^^^^^^^^^^^^^^^^^^^
  File "/home/milax/SD/sd_p1/dynamic-scaling/venv/lib/python3.11/site-packages/Pyro4/core.py", line 1141, in __init__
    self.transportServer.init(self, host, port, unixsocket)
  File "/home/milax/SD/sd_p1/dynamic-scaling/venv/lib/python3.11/site-packages/Pyro4/socketserver/threadpoolserver.py", line 129, in init
    self.sock = socketutil.createSocket(bind=bind_location,
                ^^^^^^^^^^^^^^^^^^^^^^^^^^^^^^^^^^^^^^^^^^^
  File "/home/milax/SD/sd_p1/dynamic-scaling/venv/lib/python3.11/site-packages/Pyro4/socketutil.py", line 300, in createSocket
    sock.bind(bind)
OSError: [Errno 98] Address already in use
Insult Filter service running at port 50152 with name InsultFilterService_0
Traceback (most recent call last):
  File "/home/milax/SD/sd_p1/dynamic-scaling/InsultFilterService/server.py", line 103, in <module>
    daemon = Pyro4.Daemon(port=port)
             ^^^^^^^^^^^^^^^^^^^^^^^
  File "/home/milax/SD/sd_p1/dynamic-scaling/venv/lib/python3.11/site-packages/Pyro4/core.py", line 1141, in __init__
    self.transportServer.init(self, host, port, unixsocket)
  File "/home/milax/SD/sd_p1/dynamic-scaling/venv/lib/python3.11/site-packages/Pyro4/socketserver/threadpoolserver.py", line 129, in init
    self.sock = socketutil.createSocket(bind=bind_location,
                ^^^^^^^^^^^^^^^^^^^^^^^^^^^^^^^^^^^^^^^^^^^
  File "/home/milax/SD/sd_p1/dynamic-scaling/venv/lib/python3.11/site-packages/Pyro4/socketutil.py", line 300, in createSocket
    sock.bind(bind)
OSError: [Errno 98] Address already in use
Insult Filter service running at port 50152 with name InsultFilterService_0
Insult Filter service running at port 50152 with name InsultFilterService_0
